<?xml version="1.0" ?>
<robot name="jethexa">
  <mujoco>
    <compiler meshdir="/home/ubuntu/ros2_ws/src/jethexa_description/meshes/simplify"
              balanceinertia="true"
              strippath="false"/>
  </mujoco>
  <material name="black">
    <color rgba="0.0 0.0 0.0 1.0"/>
  </material>
  <material name="blue">
    <color rgba="0.0 0.0 0.8 1.0"/>
  </material>
  <material name="green">
    <color rgba="0.0 0.8 0.0 1.0"/>
  </material>
  <material name="grey">
    <color rgba="0.2 0.2 0.2 1.0"/>
  </material>
  <material name="orange">
    <color rgba="1.0 0.4235294117647059 0.0392156862745098 1.0"/>
  </material>
  <material name="brown">
    <color rgba="0.8705882352941177 0.8117647058823529 0.7647058823529411 1.0"/>
  </material>
  <material name="red">
    <color rgba="0.8 0.0 0.0 1.0"/>
  </material>
  <material name="yellow">
    <color rgba="1.0 1.0 0.0 1.0"/>
  </material>
  <material name="white">
    <color rgba="1.0 1.0 1.0 1.0"/>
  </material>
  <!-- Used for fixing robot -->
  <link name="base_link"/>
  <joint name="base_joint" type="fixed">
    <parent link="base_link"/>
    <child link="body_link"/>
    <origin rpy="0 0 0" xyz="0 0 0.075"/>
  </joint>
  <link name="body_link">
    <visual name="body_link_visual_a">
      <origin rpy="0.0 0.0 0.0" xyz="0.0 0.0 0.0"/>
      <geometry>
        <mesh filename="/home/ubuntu/ros2_ws/src/jethexa_description/meshes/simplify/body_a.stl" scale="1.0 1.0 1.0"/>
      </geometry>
      <material name="">
        <color rgba="0.2 0.2 0.2 1"/>
      </material>
    </visual>
    <visual name="body_link_visual_b">
      <origin rpy="0.0 0.0 0.0" xyz="0.0 0.0 0.0"/>
      <geometry>
        <mesh filename="/home/ubuntu/ros2_ws/src/jethexa_description/meshes/simplify/body_b.stl" scale="1.0 1.0 1.0"/>
      </geometry>
      <material name="">
        <color rgba="0.4 0.9 0.4 1"/>
      </material>
    </visual>
    <collision name="body_link_collision">
      <origin rpy="0.0 0.0 0.0" xyz="0.0 0.0 0.0"/>
      <geometry>
        <mesh filename="/home/ubuntu/ros2_ws/src/jethexa_description/meshes/simplify/body.stl" scale="1.0 1.0 1.0"/>
      </geometry>
    </collision>
    <collision name="body_link_collision_b">
      <origin rpy="0.0 0.0 0.0" xyz="0.0 0.0 -0.0"/>
      <geometry>
        <mesh filename="/home/ubuntu/ros2_ws/src/jethexa_description/meshes/simplify/body_b.stl" scale="1.0 1.0 1.0"/>
      </geometry>
    </collision>
    <inertial>
      <origin rpy="0.0 0.0 0.0" xyz="0.0 0.0 0.0"/>
      <mass value="1"/>
      <inertia ixx="1.0" ixy="0.0" ixz="0.0" iyy="1.0" iyz="0.0" izz="1.0"/>
    </inertial>
  </link>
  <!-- leg position -->
  <joint name="leg_center_joint_RR" type="fixed">
    <origin rpy="0.0 0.0 0.0" xyz="-0.093205 -0.05098 0.0"/>
    <parent link="body_link"/>
    <child link="leg_center_RR"/>
  </joint>
  <link name="leg_center_RR">
    <visual>
      <origin xyz="0 0 0" rpy="0 0 0"/>
      <geometry>
        <box size="0.001 0.001 0.001"/>
      </geometry>
    </visual>
    <inertial>
      <origin rpy="0.0 0.0 0.0" xyz="0.0 0.0 0.0"/>
      <mass value="1"/>
      <inertia ixx="1.0" ixy="0.0" ixz="0.0" iyy="1.0" iyz="0.0" izz="1.0"/>
    </inertial>
  </link>
  <!-- coxa -->
  <joint name="coxa_joint_RR" type="revolute">
    <origin rpy="0.0 0.0 -2.356194490192345" xyz="0.0 0.0 0.0"/>
    <parent link="leg_center_RR"/>
    <child link="coxa_RR"/>
    <axis xyz="0.0 0.0 1.0"/>
    <limit effort="6.0" lower="-3.14" upper="3.14" velocity="0.524"/>
    <dynamics damping="0.7"/>
  </joint>
  <link name="coxa_RR">
    <visual name="coxa_RR_visual">
      <origin rpy="0.0 0.0 0.0" xyz="0.0 0.0 0.0"/>
      <geometry>
        <mesh filename="/home/ubuntu/ros2_ws/src/jethexa_description/meshes/simplify/coxa.stl" scale="1.0 1.0 1.0"/>
      </geometry>
      <material name="">
        <color rgba="0.4 0.9 0.4 1"/>
      </material>
    </visual>
    <collision name="coxa_RR_collision">
      <origin rpy="0.0 0.0 0.0" xyz="0.0 0.0 0.0"/>
      <geometry>
        <mesh filename="/home/ubuntu/ros2_ws/src/jethexa_description/meshes/simplify/coxa.stl" scale="1.0 1.0 1.0"/>
      </geometry>
    </collision>
    <inertial>
      <origin rpy="0.0 0.0 0.0" xyz="0.0 0.0 0.0"/>
      <mass value="1"/>
      <inertia ixx="1.0" ixy="0.0" ixz="0.0" iyy="1.0" iyz="0.0" izz="1.0"/>
    </inertial>
  </link>
  <!-- femur -->
  <joint name="femur_joint_RR" type="revolute">
    <origin rpy="1.5707963267948966 0.0 0.0" xyz="0.04505032 0.0 0.0"/>
    <parent link="coxa_RR"/>
    <child link="femur_RR"/>
    <axis xyz="0.0 0.0 1"/>
    <limit effort="6.0" lower="-3.14" upper="3.14" velocity="0.524"/>
    <dynamics damping="0.7"/>
  </joint>
  <link name="femur_RR">
    <visual name="femur_RR_visual">
      <origin rpy="0.0 0.0 0.0" xyz="0.0 0.0 0.0"/>
      <geometry>
        <mesh filename="/home/ubuntu/ros2_ws/src/jethexa_description/meshes/simplify/R_femur.stl" scale="1.0 1.0 1.0"/>
      </geometry>
      <material name="">
        <color rgba="0.2 0.2 0.2 1"/>
      </material>
    </visual>
    <collision name="femur_RR_collision">
      <origin rpy="0.0 0.0 0" xyz="0.0 0.0 0.0"/>
      <geometry>
        <mesh filename="/home/ubuntu/ros2_ws/src/jethexa_description/meshes/simplify/R_femur.stl" scale="1.0 1.0 1.0"/>
      </geometry>
      <material name="">
        <color rgba="0.2 0.2 0.2 1"/>
      </material>
    </collision>
    <inertial>
      <origin rpy="0.0 0.0 1.0" xyz="0.0 0.0 0.0"/>
      <mass value="1"/>
      <inertia ixx="1.0" ixy="0.0" ixz="0.0" iyy="1.0" iyz="0.0" izz="1.0"/>
    </inertial>
  </link>
  <!-- tibia -->
  <joint name="tibia_joint_RR" type="revolute">
    <origin rpy="0.0 0.0 -1.4835298641951802" xyz="0.07703 0.0 0.0"/>
    <parent link="femur_RR"/>
    <child link="tibia_RR"/>
    <axis xyz="0.0 0.0 1"/>
    <limit effort="6.0" lower="-3.14" upper="3.14" velocity="0.524"/>
    <dynamics damping="0.7"/>
  </joint>
  <link name="tibia_RR">
    <visual name="tibia_RR_visual_b">
      <origin rpy="0.0 0.0 -0.08727" xyz="0.0 0.0 0.0"/>
      <geometry>
        <mesh filename="/home/ubuntu/ros2_ws/src/jethexa_description/meshes/simplify/R_tibia_b.stl" scale="1.0 1.0 1.0"/>
      </geometry>
      <material name="">
        <color rgba="0.4 0.9 0.4 1"/>
      </material>
    </visual>
    <visual name="tibia_RR_visual_a">
      <origin rpy="0.0 0.0 -0.08727" xyz="0.0 0.0 0.0"/>
      <geometry>
        <mesh filename="/home/ubuntu/ros2_ws/src/jethexa_description/meshes/simplify/R_tibia_a.stl" scale="1.0 1.0 1.0"/>
      </geometry>
      <material name="">
        <color rgba="0.2 0.2 0.2 1"/>
      </material>
    </visual>
    <collision name="tibia_RR_collision">
      <origin rpy="0.0 0.0 -0.08727" xyz="0.0 0.0 0.0"/>
      <geometry>
        <mesh filename="/home/ubuntu/ros2_ws/src/jethexa_description/meshes/simplify/R_tibia.stl" scale="1.0 1.0 1.0"/>
      </geometry>
    </collision>
    <inertial>
      <origin rpy="0.0 0.0 0.0" xyz="0.0 0.0 0.0"/>
      <mass value="1"/>
      <inertia ixx="1.0" ixy="0.0" ixz="0.0" iyy="1.0" iyz="0.0" izz="1.0"/>
    </inertial>
  </link>
  <!-- END -->
  <joint name="end_jointRR" type="fixed">
    <origin rpy="0.0 0.0 0.0" xyz="0.123 0.0 0.0"/>
    <parent link="tibia_RR"/>
    <child link="end_RR"/>
    <axis xyz="0.0 0.0 0.0"/>
  </joint>
  <link name="end_RR">
        </link>
  <!-- leg position -->
  <joint name="leg_center_joint_RM" type="fixed">
    <origin rpy="0.0 0.0 0.0" xyz="0.0 -0.073535 0.0"/>
    <parent link="body_link"/>
    <child link="leg_center_RM"/>
  </joint>
  <link name="leg_center_RM">
    <visual>
      <origin xyz="0 0 0" rpy="0 0 0"/>
      <geometry>
        <box size="0.001 0.001 0.001"/>
      </geometry>
    </visual>
    <inertial>
      <origin rpy="0.0 0.0 0.0" xyz="0.0 0.0 0.0"/>
      <mass value="1"/>
      <inertia ixx="1.0" ixy="0.0" ixz="0.0" iyy="1.0" iyz="0.0" izz="1.0"/>
    </inertial>
  </link>
  <!-- coxa -->
  <joint name="coxa_joint_RM" type="revolute">
    <origin rpy="0.0 0.0 -1.5707963267948966" xyz="0.0 0.0 0.0"/>
    <parent link="leg_center_RM"/>
    <child link="coxa_RM"/>
    <axis xyz="0.0 0.0 1.0"/>
    <limit effort="6.0" lower="-3.14" upper="3.14" velocity="0.524"/>
    <dynamics damping="0.7"/>
  </joint>
  <link name="coxa_RM">
    <visual name="coxa_RM_visual">
      <origin rpy="0.0 0.0 0.0" xyz="0.0 0.0 0.0"/>
      <geometry>
        <mesh filename="/home/ubuntu/ros2_ws/src/jethexa_description/meshes/simplify/coxa.stl" scale="1.0 1.0 1.0"/>
      </geometry>
      <material name="">
        <color rgba="0.4 0.9 0.4 1"/>
      </material>
    </visual>
    <collision name="coxa_RM_collision">
      <origin rpy="0.0 0.0 0.0" xyz="0.0 0.0 0.0"/>
      <geometry>
        <mesh filename="/home/ubuntu/ros2_ws/src/jethexa_description/meshes/simplify/coxa.stl" scale="1.0 1.0 1.0"/>
      </geometry>
    </collision>
    <inertial>
      <origin rpy="0.0 0.0 0.0" xyz="0.0 0.0 0.0"/>
      <mass value="1"/>
      <inertia ixx="1.0" ixy="0.0" ixz="0.0" iyy="1.0" iyz="0.0" izz="1.0"/>
    </inertial>
  </link>
  <!-- femur -->
  <joint name="femur_joint_RM" type="revolute">
    <origin rpy="1.5707963267948966 0.0 0.0" xyz="0.04505032 0.0 0.0"/>
    <parent link="coxa_RM"/>
    <child link="femur_RM"/>
    <axis xyz="0.0 0.0 1"/>
    <limit effort="6.0" lower="-3.14" upper="3.14" velocity="0.524"/>
    <dynamics damping="0.7"/>
  </joint>
  <link name="femur_RM">
    <visual name="femur_RM_visual">
      <origin rpy="0.0 0.0 0.0" xyz="0.0 0.0 0.0"/>
      <geometry>
        <mesh filename="/home/ubuntu/ros2_ws/src/jethexa_description/meshes/simplify/R_femur.stl" scale="1.0 1.0 1.0"/>
      </geometry>
      <material name="">
        <color rgba="0.2 0.2 0.2 1"/>
      </material>
    </visual>
    <collision name="femur_RM_collision">
      <origin rpy="0.0 0.0 0" xyz="0.0 0.0 0.0"/>
      <geometry>
        <mesh filename="/home/ubuntu/ros2_ws/src/jethexa_description/meshes/simplify/R_femur.stl" scale="1.0 1.0 1.0"/>
      </geometry>
      <material name="">
        <color rgba="0.2 0.2 0.2 1"/>
      </material>
    </collision>
    <inertial>
      <origin rpy="0.0 0.0 1.0" xyz="0.0 0.0 0.0"/>
      <mass value="1"/>
      <inertia ixx="1.0" ixy="0.0" ixz="0.0" iyy="1.0" iyz="0.0" izz="1.0"/>
    </inertial>
  </link>
  <!-- tibia -->
  <joint name="tibia_joint_RM" type="revolute">
    <origin rpy="0.0 0.0 -1.4835298641951802" xyz="0.07703 0.0 0.0"/>
    <parent link="femur_RM"/>
    <child link="tibia_RM"/>
    <axis xyz="0.0 0.0 1"/>
    <limit effort="6.0" lower="-3.14" upper="3.14" velocity="0.524"/>
    <dynamics damping="0.7"/>
  </joint>
  <link name="tibia_RM">
    <visual name="tibia_RM_visual_a">
      <origin rpy="0.0 0.0 -0.08727" xyz="0.0 0.0 0.0"/>
      <geometry>
        <mesh filename="/home/ubuntu/ros2_ws/src/jethexa_description/meshes/simplify/R_tibia_b.stl" scale="1.0 1.0 1.0"/>
      </geometry>
      <material name="">
        <color rgba="0.4 0.9 0.4 1"/>
      </material>
    </visual>
    <visual name="tibia_RM_visual_b">
      <origin rpy="0.0 0.0 -0.08727" xyz="0.0 0.0 0.0"/>
      <geometry>
        <mesh filename="/home/ubuntu/ros2_ws/src/jethexa_description/meshes/simplify/R_tibia_a.stl" scale="1.0 1.0 1.0"/>
      </geometry>
      <material name="">
        <color rgba="0.2 0.2 0.2 1"/>
      </material>
    </visual>
    <collision name="tibia_RM_collision">
      <origin rpy="0.0 0.0 -0.08727" xyz="0.0 0.0 0.0"/>
      <geometry>
        <mesh filename="/home/ubuntu/ros2_ws/src/jethexa_description/meshes/simplify/R_tibia.stl" scale="1.0 1.0 1.0"/>
      </geometry>
    </collision>
    <inertial>
      <origin rpy="0.0 0.0 0.0" xyz="0.0 0.0 0.0"/>
      <mass value="1"/>
      <inertia ixx="1.0" ixy="0.0" ixz="0.0" iyy="1.0" iyz="0.0" izz="1.0"/>
    </inertial>
  </link>
  <!-- END -->
  <joint name="end_jointRM" type="fixed">
    <origin rpy="0.0 0.0 0.0" xyz="0.123 0.0 0.0"/>
    <parent link="tibia_RM"/>
    <child link="end_RM"/>
    <axis xyz="0.0 0.0 0.0"/>
  </joint>
  <link name="end_RM">
        </link>
  <!-- leg position -->
  <joint name="leg_center_joint_RF" type="fixed">
    <origin rpy="0.0 0.0 0.0" xyz="0.093205 -0.05098 0.0"/>
    <parent link="body_link"/>
    <child link="leg_center_RF"/>
  </joint>
  <link name="leg_center_RF">
    <visual>
      <origin xyz="0 0 0" rpy="0 0 0"/>
      <geometry>
        <box size="0.001 0.001 0.001"/>
      </geometry>
    </visual>
    <inertial>
      <origin rpy="0.0 0.0 0.0" xyz="0.0 0.0 0.0"/>
      <mass value="1"/>
      <inertia ixx="1.0" ixy="0.0" ixz="0.0" iyy="1.0" iyz="0.0" izz="1.0"/>
    </inertial>
  </link>
  <!-- coxa -->
  <joint name="coxa_joint_RF" type="revolute">
    <origin rpy="0.0 0.0 -0.7853981633974483" xyz="0.0 0.0 0.0"/>
    <parent link="leg_center_RF"/>
    <child link="coxa_RF"/>
    <axis xyz="0.0 0.0 1.0"/>
    <limit effort="6.0" lower="-3.14" upper="3.14" velocity="0.524"/>
    <dynamics damping="0.7"/>
  </joint>
  <link name="coxa_RF">
    <visual name="coxa_RF_visual">
      <origin rpy="0.0 0.0 0.0" xyz="0.0 0.0 0.0"/>
      <geometry>
        <mesh filename="/home/ubuntu/ros2_ws/src/jethexa_description/meshes/simplify/coxa.stl" scale="1.0 1.0 1.0"/>
      </geometry>
      <material name="">
        <color rgba="0.4 0.9 0.4 1"/>
      </material>
    </visual>
    <collision name="coxa_RF_collision">
      <origin rpy="0.0 0.0 0.0" xyz="0.0 0.0 0.0"/>
      <geometry>
        <mesh filename="/home/ubuntu/ros2_ws/src/jethexa_description/meshes/simplify/coxa.stl" scale="1.0 1.0 1.0"/>
      </geometry>
    </collision>
    <inertial>
      <origin rpy="0.0 0.0 0.0" xyz="0.0 0.0 0.0"/>
      <mass value="1"/>
      <inertia ixx="1.0" ixy="0.0" ixz="0.0" iyy="1.0" iyz="0.0" izz="1.0"/>
    </inertial>
  </link>
  <!-- femur -->
  <joint name="femur_joint_RF" type="revolute">
    <origin rpy="1.5707963267948966 0.0 0.0" xyz="0.04505032 0.0 0.0"/>
    <parent link="coxa_RF"/>
    <child link="femur_RF"/>
    <axis xyz="0.0 0.0 1"/>
    <limit effort="6.0" lower="-3.14" upper="3.14" velocity="0.524"/>
    <dynamics damping="0.7"/>
  </joint>
  <link name="femur_RF">
    <visual name="femur_RF_visual">
      <origin rpy="0.0 0.0 0.0" xyz="0.0 0.0 0.0"/>
      <geometry>
        <mesh filename="/home/ubuntu/ros2_ws/src/jethexa_description/meshes/simplify/R_femur.stl" scale="1.0 1.0 1.0"/>
      </geometry>
      <material name="">
        <color rgba="0.2 0.2 0.2 1"/>
      </material>
    </visual>
    <collision name="femur_RF_collision">
      <origin rpy="0.0 0.0 0" xyz="0.0 0.0 0.0"/>
      <geometry>
        <mesh filename="/home/ubuntu/ros2_ws/src/jethexa_description/meshes/simplify/R_femur.stl" scale="1.0 1.0 1.0"/>
      </geometry>
      <material name="">
        <color rgba="0.2 0.2 0.2 1"/>
      </material>
    </collision>
    <inertial>
      <origin rpy="0.0 0.0 1.0" xyz="0.0 0.0 0.0"/>
      <mass value="1"/>
      <inertia ixx="1.0" ixy="0.0" ixz="0.0" iyy="1.0" iyz="0.0" izz="1.0"/>
    </inertial>
  </link>
  <!-- tibia -->
  <joint name="tibia_joint_RF" type="revolute">
    <origin rpy="0.0 0.0 -1.4835298641951802" xyz="0.07703 0.0 0.0"/>
    <parent link="femur_RF"/>
    <child link="tibia_RF"/>
    <axis xyz="0.0 0.0 1"/>
    <limit effort="6.0" lower="-3.14" upper="3.14" velocity="0.524"/>
    <dynamics damping="0.7"/>
  </joint>
  <link name="tibia_RF">
    <visual name="tibia_RF_visual_a">
      <origin rpy="0.0 0.0 -0.08727" xyz="0.0 0.0 0.0"/>
      <geometry>
        <mesh filename="/home/ubuntu/ros2_ws/src/jethexa_description/meshes/simplify/R_tibia_b.stl" scale="1.0 1.0 1.0"/>
      </geometry>
      <material name="">
        <color rgba="0.4 0.9 0.4 1"/>
      </material>
    </visual>
    <visual name="tibia_RF_visual_b">
      <origin rpy="0.0 0.0 -0.08727" xyz="0.0 0.0 0.0"/>
      <geometry>
        <mesh filename="/home/ubuntu/ros2_ws/src/jethexa_description/meshes/simplify/R_tibia_a.stl" scale="1.0 1.0 1.0"/>
      </geometry>
      <material name="">
        <color rgba="0.2 0.2 0.2 1"/>
      </material>
    </visual>
    <collision name="tibia_RF_collision">
      <origin rpy="0.0 0.0 -0.08727" xyz="0.0 0.0 0.0"/>
      <geometry>
        <mesh filename="/home/ubuntu/ros2_ws/src/jethexa_description/meshes/simplify/R_tibia.stl" scale="1.0 1.0 1.0"/>
      </geometry>
    </collision>
    <inertial>
      <origin rpy="0.0 0.0 0.0" xyz="0.0 0.0 0.0"/>
      <mass value="1"/>
      <inertia ixx="1.0" ixy="0.0" ixz="0.0" iyy="1.0" iyz="0.0" izz="1.0"/>
    </inertial>
  </link>
  <!-- END -->
  <joint name="end_jointRF" type="fixed">
    <origin rpy="0.0 0.0 0.0" xyz="0.123 0.0 0.0"/>
    <parent link="tibia_RF"/>
    <child link="end_RF"/>
    <axis xyz="0.0 0.0 0.0"/>
  </joint>
  <link name="end_RF">
        </link>
  <!-- leg position -->
  <joint name="leg_center_joint_LR" type="fixed">
    <origin rpy="0.0 0.0 0.0" xyz="-0.093205 0.05098 0.0"/>
    <parent link="body_link"/>
    <child link="leg_center_LR"/>
  </joint>
  <link name="leg_center_LR">
    <visual>
      <origin xyz="0 0 0" rpy="0 0 0"/>
      <geometry>
        <box size="0.001 0.001 0.001"/>
      </geometry>
    </visual>
    <inertial>
      <origin rpy="0.0 0.0 0.0" xyz="0.0 0.0 0.0"/>
      <mass value="1"/>
      <inertia ixx="1.0" ixy="0.0" ixz="0.0" iyy="1.0" iyz="0.0" izz="1.0"/>
    </inertial>
  </link>
  <!-- coxa -->
  <joint name="coxa_joint_LR" type="revolute">
    <origin rpy="0.0 0.0 2.356194490192345" xyz="0.0 0.0 0.0"/>
    <parent link="leg_center_LR"/>
    <child link="coxa_LR"/>
    <axis xyz="0.0 0.0 1.0"/>
    <limit effort="6.0" lower="-3.14" upper="3.14" velocity="0.524"/>
    <dynamics damping="0.7"/>
  </joint>
  <link name="coxa_LR">
    <visual name="coxa_LR_visual">
      <origin rpy="0.0 0.0 0.0" xyz="0.0 0.0 0.0"/>
      <geometry>
        <mesh filename="/home/ubuntu/ros2_ws/src/jethexa_description/meshes/simplify/coxa.stl" scale="1.0 1.0 1.0"/>
      </geometry>
      <material name="">
        <color rgba="0.4 0.9 0.4 1"/>
      </material>
    </visual>
    <collision name="coxa_LR_collision">
      <origin rpy="0.0 0.0 0.0" xyz="0.0 0.0 0.0"/>
      <geometry>
        <mesh filename="/home/ubuntu/ros2_ws/src/jethexa_description/meshes/simplify/coxa.stl" scale="1.0 1.0 1.0"/>
      </geometry>
    </collision>
    <inertial>
      <origin rpy="0.0 0.0 0.0" xyz="0.0 0.0 0.0"/>
      <mass value="1"/>
      <inertia ixx="1.0" ixy="0.0" ixz="0.0" iyy="1.0" iyz="0.0" izz="1.0"/>
    </inertial>
  </link>
  <!-- femur -->
  <joint name="femur_joint_LR" type="revolute">
    <origin rpy="-1.5707963267948966 0.0 0.0" xyz="0.04505032 0.0 0.0"/>
    <parent link="coxa_LR"/>
    <child link="femur_LR"/>
    <axis xyz="0.0 0.0 -1"/>
    <limit effort="6.0" lower="-3.14" upper="3.14" velocity="0.524"/>
    <dynamics damping="0.7"/>
  </joint>
  <link name="femur_LR">
    <visual name="femur_LR_visual">
      <origin rpy="0.0 0.0 0.0" xyz="0.0 0.0 0.0"/>
      <geometry>
        <mesh filename="/home/ubuntu/ros2_ws/src/jethexa_description/meshes/simplify/L_femur.stl" scale="1.0 1.0 1.0"/>
      </geometry>
      <material name="">
        <color rgba="0.2 0.2 0.2 1"/>
      </material>
    </visual>
    <collision name="femur_LR_collision">
      <origin rpy="0.0 0.0 0" xyz="0.0 0.0 0.0"/>
      <geometry>
        <mesh filename="/home/ubuntu/ros2_ws/src/jethexa_description/meshes/simplify/L_femur.stl" scale="1.0 1.0 1.0"/>
      </geometry>
      <material name="">
        <color rgba="0.2 0.2 0.2 1"/>
      </material>
    </collision>
    <inertial>
      <origin rpy="0.0 0.0 1.0" xyz="0.0 0.0 0.0"/>
      <mass value="1"/>
      <inertia ixx="1.0" ixy="0.0" ixz="0.0" iyy="1.0" iyz="0.0" izz="1.0"/>
    </inertial>
  </link>
  <!-- tibia -->
  <joint name="tibia_joint_LR" type="revolute">
    <origin rpy="0.0 0.0 1.4835298641951802" xyz="0.07703 0.0 0.0"/>
    <parent link="femur_LR"/>
    <child link="tibia_LR"/>
    <axis xyz="0.0 0.0 -1"/>
    <limit effort="6.0" lower="-3.14" upper="3.14" velocity="0.524"/>
    <dynamics damping="0.7"/>
  </joint>
  <link name="tibia_LR">
    <visual name="tibia_LR_visual_b">
      <origin rpy="0.0 0.0 0.08727" xyz="0.0 0.0 0.0"/>
      <geometry>
        <mesh filename="/home/ubuntu/ros2_ws/src/jethexa_description/meshes/simplify/L_tibia_b.stl" scale="1.0 1.0 1.0"/>
      </geometry>
      <material name="">
        <color rgba="0.4 0.9 0.4 1"/>
      </material>
    </visual>
    <visual name="tibia_LR_visual_a">
      <origin rpy="0.0 0.0 0.08727" xyz="0.0 0.0 0.0"/>
      <geometry>
        <mesh filename="/home/ubuntu/ros2_ws/src/jethexa_description/meshes/simplify/L_tibia_a.stl" scale="1.0 1.0 1.0"/>
      </geometry>
      <material name="">
        <color rgba="0.2 0.2 0.2 1"/>
      </material>
    </visual>
    <collision name="tibia_LR_collision">
      <origin rpy="0.0 0.0 0.08727" xyz="0.0 0.0 0.0"/>
      <geometry>
        <mesh filename="/home/ubuntu/ros2_ws/src/jethexa_description/meshes/simplify/L_tibia.stl" scale="1.0 1.0 1.0"/>
      </geometry>
    </collision>
    <inertial>
      <origin rpy="0.0 0.0 0.0" xyz="0.0 0.0 0.0"/>
      <mass value="1"/>
      <inertia ixx="1.0" ixy="0.0" ixz="0.0" iyy="1.0" iyz="0.0" izz="1.0"/>
    </inertial>
  </link>
  <!-- END -->
  <joint name="end_jointLR" type="fixed">
    <origin rpy="0.0 0.0 0.0" xyz="0.123 0.0 0.0"/>
    <parent link="tibia_LR"/>
    <child link="end_LR"/>
    <axis xyz="0.0 0.0 0.0"/>
  </joint>
  <link name="end_LR">
        </link>
  <!-- leg position -->
  <joint name="leg_center_joint_LM" type="fixed">
    <origin rpy="0.0 0.0 0.0" xyz="0.0 0.07353 0.0"/>
    <parent link="body_link"/>
    <child link="leg_center_LM"/>
  </joint>
  <link name="leg_center_LM">
    <visual>
      <origin xyz="0 0 0" rpy="0 0 0"/>
      <geometry>
        <box size="0.001 0.001 0.001"/>
      </geometry>
    </visual>
    <inertial>
      <origin rpy="0.0 0.0 0.0" xyz="0.0 0.0 0.0"/>
      <mass value="1"/>
      <inertia ixx="1.0" ixy="0.0" ixz="0.0" iyy="1.0" iyz="0.0" izz="1.0"/>
    </inertial>
  </link>
  <!-- coxa -->
  <joint name="coxa_joint_LM" type="revolute">
    <origin rpy="0.0 0.0 1.5707963267948966" xyz="0.0 0.0 0.0"/>
    <parent link="leg_center_LM"/>
    <child link="coxa_LM"/>
    <axis xyz="0.0 0.0 1.0"/>
    <limit effort="6.0" lower="-3.14" upper="3.14" velocity="0.524"/>
    <dynamics damping="0.7"/>
  </joint>
  <link name="coxa_LM">
    <visual name="coxa_LM_visual">
      <origin rpy="0.0 0.0 0.0" xyz="0.0 0.0 0.0"/>
      <geometry>
        <mesh filename="/home/ubuntu/ros2_ws/src/jethexa_description/meshes/simplify/coxa.stl" scale="1.0 1.0 1.0"/>
      </geometry>
      <material name="">
        <color rgba="0.4 0.9 0.4 1"/>
      </material>
    </visual>
    <collision name="coxa_LM_collision">
      <origin rpy="0.0 0.0 0.0" xyz="0.0 0.0 0.0"/>
      <geometry>
        <mesh filename="/home/ubuntu/ros2_ws/src/jethexa_description/meshes/simplify/coxa.stl" scale="1.0 1.0 1.0"/>
      </geometry>
    </collision>
    <inertial>
      <origin rpy="0.0 0.0 0.0" xyz="0.0 0.0 0.0"/>
      <mass value="1"/>
      <inertia ixx="1.0" ixy="0.0" ixz="0.0" iyy="1.0" iyz="0.0" izz="1.0"/>
    </inertial>
  </link>
  <!-- femur -->
  <joint name="femur_joint_LM" type="revolute">
    <origin rpy="-1.5707963267948966 0.0 0.0" xyz="0.04505032 0.0 0.0"/>
    <parent link="coxa_LM"/>
    <child link="femur_LM"/>
    <axis xyz="0.0 0.0 -1"/>
    <limit effort="6.0" lower="-3.14" upper="3.14" velocity="0.524"/>
    <dynamics damping="0.7"/>
  </joint>
  <link name="femur_LM">
    <visual name="femur_LM_visual">
      <origin rpy="0.0 0.0 0.0" xyz="0.0 0.0 0.0"/>
      <geometry>
        <mesh filename="/home/ubuntu/ros2_ws/src/jethexa_description/meshes/simplify/L_femur.stl" scale="1.0 1.0 1.0"/>
      </geometry>
      <material name="">
        <color rgba="0.2 0.2 0.2 1"/>
      </material>
    </visual>
    <collision name="femur_LM_collision">
      <origin rpy="0.0 0.0 0" xyz="0.0 0.0 0.0"/>
      <geometry>
        <mesh filename="/home/ubuntu/ros2_ws/src/jethexa_description/meshes/simplify/L_femur.stl" scale="1.0 1.0 1.0"/>
      </geometry>
      <material name="">
        <color rgba="0.2 0.2 0.2 1"/>
      </material>
    </collision>
    <inertial>
      <origin rpy="0.0 0.0 1.0" xyz="0.0 0.0 0.0"/>
      <mass value="1"/>
      <inertia ixx="1.0" ixy="0.0" ixz="0.0" iyy="1.0" iyz="0.0" izz="1.0"/>
    </inertial>
  </link>
  <!-- tibia -->
  <joint name="tibia_joint_LM" type="revolute">
    <origin rpy="0.0 0.0 1.4835298641951802" xyz="0.07703 0.0 0.0"/>
    <parent link="femur_LM"/>
    <child link="tibia_LM"/>
    <axis xyz="0.0 0.0 -1"/>
    <limit effort="6.0" lower="-3.14" upper="3.14" velocity="0.524"/>
    <dynamics damping="0.7"/>
  </joint>
  <link name="tibia_LM">
    <visual name="tibia_LM_visual_b">
      <origin rpy="0.0 0.0 0.08727" xyz="0.0 0.0 0.0"/>
      <geometry>
        <mesh filename="/home/ubuntu/ros2_ws/src/jethexa_description/meshes/simplify/L_tibia_b.stl" scale="1.0 1.0 1.0"/>
      </geometry>
      <material name="">
        <color rgba="0.4 0.9 0.4 1"/>
      </material>
    </visual>
    <visual name="tibia_LM_visual_a">
      <origin rpy="0.0 0.0 0.08727" xyz="0.0 0.0 0.0"/>
      <geometry>
        <mesh filename="/home/ubuntu/ros2_ws/src/jethexa_description/meshes/simplify/L_tibia_a.stl" scale="1.0 1.0 1.0"/>
      </geometry>
      <material name="">
        <color rgba="0.2 0.2 0.2 1"/>
      </material>
    </visual>
    <collision name="tibia_LM_collision">
      <origin rpy="0.0 0.0 0.08727" xyz="0.0 0.0 0.0"/>
      <geometry>
        <mesh filename="/home/ubuntu/ros2_ws/src/jethexa_description/meshes/simplify/L_tibia.stl" scale="1.0 1.0 1.0"/>
      </geometry>
    </collision>
    <inertial>
      <origin rpy="0.0 0.0 0.0" xyz="0.0 0.0 0.0"/>
      <mass value="1"/>
      <inertia ixx="1.0" ixy="0.0" ixz="0.0" iyy="1.0" iyz="0.0" izz="1.0"/>
    </inertial>
  </link>
  <!-- END -->
  <joint name="end_jointLM" type="fixed">
    <origin rpy="0.0 0.0 0.0" xyz="0.123 0.0 0.0"/>
    <parent link="tibia_LM"/>
    <child link="end_LM"/>
    <axis xyz="0.0 0.0 0.0"/>
  </joint>
  <link name="end_LM">
        </link>
  <!-- leg position -->
  <joint name="leg_center_joint_LF" type="fixed">
    <origin rpy="0.0 0.0 0.0" xyz="0.093205 0.05098 0.0"/>
    <parent link="body_link"/>
    <child link="leg_center_LF"/>
  </joint>
  <link name="leg_center_LF">
    <visual>
      <origin xyz="0 0 0" rpy="0 0 0"/>
      <geometry>
        <box size="0.001 0.001 0.001"/>
      </geometry>
    </visual>
    <inertial>
      <origin rpy="0.0 0.0 0.0" xyz="0.0 0.0 0.0"/>
      <mass value="1"/>
      <inertia ixx="1.0" ixy="0.0" ixz="0.0" iyy="1.0" iyz="0.0" izz="1.0"/>
    </inertial>
  </link>
  <!-- coxa -->
  <joint name="coxa_joint_LF" type="revolute">
    <origin rpy="0.0 0.0 0.7853981633974483" xyz="0.0 0.0 0.0"/>
    <parent link="leg_center_LF"/>
    <child link="coxa_LF"/>
    <axis xyz="0.0 0.0 1.0"/>
    <limit effort="6.0" lower="-3.14" upper="3.14" velocity="0.524"/>
    <dynamics damping="0.7"/>
  </joint>
  <link name="coxa_LF">
    <visual name="coxa_LF_visual">
      <origin rpy="0.0 0.0 0.0" xyz="0.0 0.0 0.0"/>
      <geometry>
        <mesh filename="/home/ubuntu/ros2_ws/src/jethexa_description/meshes/simplify/coxa.stl" scale="1.0 1.0 1.0"/>
      </geometry>
      <material name="">
        <color rgba="0.4 0.9 0.4 1"/>
      </material>
    </visual>
    <collision name="coxa_LF_collision">
      <origin rpy="0.0 0.0 0.0" xyz="0.0 0.0 0.0"/>
      <geometry>
        <mesh filename="/home/ubuntu/ros2_ws/src/jethexa_description/meshes/simplify/coxa.stl" scale="1.0 1.0 1.0"/>
      </geometry>
    </collision>
    <inertial>
      <origin rpy="0.0 0.0 0.0" xyz="0.0 0.0 0.0"/>
      <mass value="1"/>
      <inertia ixx="1.0" ixy="0.0" ixz="0.0" iyy="1.0" iyz="0.0" izz="1.0"/>
    </inertial>
  </link>
  <!-- femur -->
  <joint name="femur_joint_LF" type="revolute">
    <origin rpy="-1.5707963267948966 0.0 0.0" xyz="0.04505032 0.0 0.0"/>
    <parent link="coxa_LF"/>
    <child link="femur_LF"/>
    <axis xyz="0.0 0.0 -1"/>
    <limit effort="6.0" lower="-3.14" upper="3.14" velocity="0.524"/>
    <dynamics damping="0.7"/>
  </joint>
  <link name="femur_LF">
    <visual name="femur_LF_visual">
      <origin rpy="0.0 0.0 0.0" xyz="0.0 0.0 0.0"/>
      <geometry>
        <mesh filename="/home/ubuntu/ros2_ws/src/jethexa_description/meshes/simplify/L_femur.stl" scale="1.0 1.0 1.0"/>
      </geometry>
      <material name="">
        <color rgba="0.2 0.2 0.2 1"/>
      </material>
    </visual>
    <collision name="femur_LF_collision">
      <origin rpy="0.0 0.0 0" xyz="0.0 0.0 0.0"/>
      <geometry>
        <mesh filename="/home/ubuntu/ros2_ws/src/jethexa_description/meshes/simplify/L_femur.stl" scale="1.0 1.0 1.0"/>
      </geometry>
      <material name="">
        <color rgba="0.2 0.2 0.2 1"/>
      </material>
    </collision>
    <inertial>
      <origin rpy="0.0 0.0 1.0" xyz="0.0 0.0 0.0"/>
      <mass value="1"/>
      <inertia ixx="1.0" ixy="0.0" ixz="0.0" iyy="1.0" iyz="0.0" izz="1.0"/>
    </inertial>
  </link>
  <!-- tibia -->
  <joint name="tibia_joint_LF" type="revolute">
    <origin rpy="0.0 0.0 1.4835298641951802" xyz="0.07703 0.0 0.0"/>
    <parent link="femur_LF"/>
    <child link="tibia_LF"/>
    <axis xyz="0.0 0.0 -1"/>
    <limit effort="6.0" lower="-3.14" upper="3.14" velocity="0.524"/>
    <dynamics damping="0.7"/>
  </joint>
  <link name="tibia_LF">
    <visual name="tibia_LF_visual_b">
      <origin rpy="0.0 0.0 0.08727" xyz="0.0 0.0 0.0"/>
      <geometry>
        <mesh filename="/home/ubuntu/ros2_ws/src/jethexa_description/meshes/simplify/L_tibia_b.stl" scale="1.0 1.0 1.0"/>
      </geometry>
      <material name="">
        <color rgba="0.4 0.9 0.4 1"/>
      </material>
    </visual>
    <visual name="tibia_LF_visual_a">
      <origin rpy="0.0 0.0 0.08727" xyz="0.0 0.0 0.0"/>
      <geometry>
        <mesh filename="/home/ubuntu/ros2_ws/src/jethexa_description/meshes/simplify/L_tibia_a.stl" scale="1.0 1.0 1.0"/>
      </geometry>
      <material name="">
        <color rgba="0.2 0.2 0.2 1"/>
      </material>
    </visual>
    <collision name="tibia_LF_collision">
      <origin rpy="0.0 0.0 0.08727" xyz="0.0 0.0 0.0"/>
      <geometry>
        <mesh filename="/home/ubuntu/ros2_ws/src/jethexa_description/meshes/simplify/L_tibia.stl" scale="1.0 1.0 1.0"/>
      </geometry>
    </collision>
    <inertial>
      <origin rpy="0.0 0.0 0.0" xyz="0.0 0.0 0.0"/>
      <mass value="1"/>
      <inertia ixx="1.0" ixy="0.0" ixz="0.0" iyy="1.0" iyz="0.0" izz="1.0"/>
    </inertial>
  </link>
  <!-- END -->
  <joint name="end_jointLF" type="fixed">
    <origin rpy="0.0 0.0 0.0" xyz="0.123 0.0 0.0"/>
    <parent link="tibia_LF"/>
    <child link="end_LF"/>
    <axis xyz="0.0 0.0 0.0"/>
  </joint>
  <link name="end_LF">
        </link>
</robot>
