<?xml version="1.0" ?>
<!-- =================================================================================== -->
<!-- |    This document was autogenerated by xacro from call_jethexa.xacro             | -->
<!-- |    EDITING THIS FILE BY HAND IS NOT RECOMMENDED                                 | -->
<!-- =================================================================================== -->
<robot name="jethexa_robot">
  <link name="world"/>
  <joint name="base_joint" type="fixed">
    <parent link="body_link"/>
    <child link="body_link"/>
    <origin rpy="0 0 0" xyz="0 0 0"/>
  </joint>
  <link name="body_link">
    <visual>
      <origin rpy="0.0 0.0 0.0" xyz="0.0 0.0 0.0"/>
      <geometry>
        <mesh filename="package://jethexa_description/meshes/simplify/body.stl" scale="0.001 0.001 0.001"/>
      </geometry>
      <material name="">
        <color rgba="0.7 0.7 0.7 1"/>
      </material>
    </visual>
    <collision>
      <origin rpy="0.0 0.0 0.0" xyz="0.0 0.0 0.0"/>
      <geometry>
        <mesh filename="package://jethexa_description/meshes/simplify/body.stl" scale="0.001 0.001 0.001"/>
      </geometry>
      <material name="">
        <color rgba="0.7 0.7 0.7 1"/>
      </material>
    </collision>
    <inertial>
      <origin rpy="0.0 0.0 0.0" xyz="0.0 0.0 0.0"/>
      <mass value="0.00001"/>
      <inertia ixx="1.0" ixy="0.0" ixz="0.0" iyy="1.0" iyz="0.0" izz="1.0"/>
    </inertial>
  </link>
  <!-- Head Pan and Tilt properties -->
  <joint name="head_center_joint" type="fixed">
    <parent link="body_link"/>
    <child link="head_center_link"/>
    <origin rpy="0.0 0.0 0.0" xyz="0.065455 0.0 0.0"/>
  </joint>
  <link name="head_center_link">
    <inertial>
      <origin rpy="0.0 0.0 0.0" xyz="0.0 0.0 0.0"/>
      <mass value="0.00001"/>
      <inertia ixx="1.0" ixy="0.0" ixz="0.0" iyy="1.0" iyz="0.0" izz="1.0"/>
    </inertial>
  </link>
  <joint name="head_pan_joint" type="revolute">
    <parent link="head_center_link"/>
    <child link="head_pan_link"/>
    <axis xyz="0.0 0.0 1.0"/>
    <origin rpy="0.0 0.0 0.0" xyz="0.0 0.0 0.068857338"/>
    <limit effort="10000" lower="-3.14" upper="3.14" velocity="100"/>
    <dynamics damping="0.7"/>
  </joint>
  <link name="head_pan_link">
    <visual>
      <origin rpy="0.0 0.0 0.0" xyz="0.0 0.0 0.0"/>
      <geometry>
        <mesh filename="package://jethexa_description/meshes/simplify/head_pan.stl" scale="0.001 0.001 0.001"/>
      </geometry>
      <material name="">
        <color rgba="0.7 0.7 0.7 1"/>
      </material>
    </visual>
    <collision>
      <origin rpy="0.0 0.0 0.0" xyz="0.0 0.0 0.0"/>
      <geometry>
        <mesh filename="package://jethexa_description/meshes/simplify/head_pan.stl" scale="0.001 0.001 0.001"/>
      </geometry>
      <material name="">
        <color rgba="0.7 0.7 0.7 1"/>
      </material>
    </collision>
    <inertial>
      <origin rpy="0.0 0.0 0.0" xyz="0.0 0.0 0.0"/>
      <mass value="0.00001"/>
      <inertia ixx="1.0" ixy="0.0" ixz="0.0" iyy="1.0" iyz="0.0" izz="1.0"/>
    </inertial>
  </link>
  <joint name="head_tilt_joint" type="revolute">
    <parent link="head_pan_link"/>
    <child link="head_tilt_link"/>
    <axis xyz="0.0 0.0 1.0"/>
    <origin rpy="1.5707963267948966 0.0 0.0" xyz="0.00922 0.0 0.017199"/>
    <limit effort="10000" lower="-3.14" upper="3.14" velocity="100"/>
    <dynamics damping="0.7"/>
  </joint>
  <link name="head_tilt_link">
    <visual>
      <origin rpy="0.0 0.0 0.0" xyz="0.0 0.0 0.0"/>
      <geometry>
        <mesh filename="package://jethexa_description/meshes/simplify/head_tilt.stl" scale="0.001 0.001 0.001"/>
      </geometry>
      <material name="">
        <color rgba="0.7 0.7 0.7 1"/>
      </material>
    </visual>
    <collision>
      <origin rpy="0.0 0.0 0.0" xyz="0.0 0.0 0.0"/>
      <geometry>
        <mesh filename="package://jethexa_description/meshes/simplify/head_tilt.stl" scale="0.001 0.001 0.001"/>
      </geometry>
      <material name="">
        <color rgba="0.7 0.7 0.7 1"/>
      </material>
    </collision>
    <inertial>
      <origin rpy="0.0 0.0 0.0" xyz="0.0 0.0 0.0"/>
      <mass value="0.00001"/>
      <inertia ixx="1.0" ixy="0.0" ixz="0.0" iyy="1.0" iyz="0.0" izz="1.0"/>
    </inertial>
  </link>
  <!-- leg position -->
  <joint name="leg_center_joint_RR" type="fixed">
    <origin rpy="0.0 0.0 0.0" xyz="-0.093205 -0.05098 0.0"/>
    <parent link="body_link"/>
    <child link="leg_center_RR"/>
  </joint>
  <link name="leg_center_RR">
    <inertial>
      <origin rpy="0.0 0.0 0.0" xyz="0.0 0.0 0.0"/>
      <mass value="0.00001"/>
      <inertia ixx="1.0" ixy="0.0" ixz="0.0" iyy="1.0" iyz="0.0" izz="1.0"/>
    </inertial>
  </link>
  <!-- coxa -->
  <joint name="coxa_joint_RR" type="revolute">
    <origin rpy="0.0 0.0 -2.356194490192345" xyz="0.0 0.0 0.0"/>
    <parent link="leg_center_RR"/>
    <child link="coxa_RR"/>
    <axis xyz="0.0 0.0 1.0"/>
    <limit effort="6.0" lower="-3.14" upper="3.14" velocity="0.524"/>
    <dynamics damping="0.7"/>
  </joint>
  <link name="coxa_RR">
    <visual>
      <origin rpy="0.0 0.0 0.0" xyz="0.0 0.0 0.0"/>
      <geometry>
        <mesh filename="package://jethexa_description/meshes/simplify/coxa.stl" scale="0.001 0.001 0.001"/>
      </geometry>
      <material name="">
        <color rgba="0.7 0.7 0.7 1"/>
      </material>
    </visual>
    <collision>
      <origin rpy="0.0 0.0 0.0" xyz="0.0 0.0 0.0"/>
      <geometry>
        <mesh filename="package://jethexa_description/meshes/simplify/coxa.stl" scale="0.001 0.001 0.001"/>
      </geometry>
      <material name="">
        <color rgba="0.7 0.7 0.7 1"/>
      </material>
    </collision>
    <inertial>
      <origin rpy="0.0 0.0 0.0" xyz="0.0 0.0 0.0"/>
      <mass value="0.00001"/>
      <inertia ixx="1.0" ixy="0.0" ixz="0.0" iyy="1.0" iyz="0.0" izz="1.0"/>
    </inertial>
  </link>
  <!-- femur -->
  <joint name="femur_joint_RR" type="revolute">
    <origin rpy="1.5707963267948966 0.0 0.0" xyz="0.04505032 0.0 0.0"/>
    <parent link="coxa_RR"/>
    <child link="femur_RR"/>
    <axis xyz="0.0 0.0 1"/>
    <limit effort="6.0" lower="-3.14" upper="3.14" velocity="0.524"/>
    <dynamics damping="0.7"/>
  </joint>
  <link name="femur_RR">
    <visual>
      <origin rpy="0.0 0.0 0.0" xyz="0.0 0.0 0.0"/>
      <geometry>
        <mesh filename="package://jethexa_description/meshes/simplify/R_femur.stl" scale="0.001 0.001 0.001"/>
      </geometry>
      <material name="">
        <color rgba="0.7 0.7 0.7 1"/>
      </material>
    </visual>
    <collision>
      <origin rpy="0.0 0.0 0" xyz="0.0 0.0 0.0"/>
      <geometry>
        <mesh filename="package://jethexa_description/meshes/simplify/R_femur.stl" scale="0.001 0.001 0.001"/>
      </geometry>
      <material name="">
        <color rgba="0.7 0.7 0.7 1"/>
      </material>
    </collision>
    <inertial>
      <origin rpy="0.0 0.0 1.0" xyz="0.0 0.0 0.0"/>
      <mass value="0.00001"/>
      <inertia ixx="1.0" ixy="0.0" ixz="0.0" iyy="1.0" iyz="0.0" izz="1.0"/>
    </inertial>
  </link>
  <!-- tibia -->
  <joint name="tibia_joint_RR" type="revolute">
    <origin rpy="0.0 0.0 -1.5707963267948966" xyz="0.07703 0.0 0.0"/>
    <parent link="femur_RR"/>
    <child link="tibia_RR"/>
    <axis xyz="0.0 0.0 1"/>
    <limit effort="6.0" lower="-3.14" upper="3.14" velocity="0.524"/>
    <dynamics damping="0.7"/>
  </joint>
  <link name="tibia_RR">
    <visual>
      <origin rpy="0.0 0.0 0.0" xyz="0.0 0.0 0.0"/>
      <geometry>
        <mesh filename="package://jethexa_description/meshes/simplify/R_tibia.stl" scale="0.001 0.001 0.001"/>
      </geometry>
      <material name="">
        <color rgba="0.7 0.7 0.7 1"/>
      </material>
    </visual>
    <collision>
      <origin rpy="0.0 0.0 0.0" xyz="0.0 0.0 0.0"/>
      <geometry>
        <mesh filename="package://jethexa_description/meshes/simplify/R_tibia.stl" scale="0.001 0.001 0.001"/>
      </geometry>
      <material name="">
        <color rgba="0.7 0.7 0.7 1"/>
      </material>
    </collision>
    <inertial>
      <origin rpy="0.0 0.0 0.0" xyz="0.0 0.0 0.0"/>
      <mass value="0.00001"/>
      <inertia ixx="1.0" ixy="0.0" ixz="0.0" iyy="1.0" iyz="0.0" izz="1.0"/>
    </inertial>
  </link>
  <!-- END -->
  <joint name="end_jointRR" type="fixed">
    <origin rpy="0.0 0.0 0.0" xyz="0.12 0.0 0.0"/>
    <parent link="tibia_RR"/>
    <child link="end_RR"/>
    <axis xyz="0.0 0.0 0.0"/>
  </joint>
  <link name="end_RR">
        </link>
  <!-- leg position -->
  <joint name="leg_center_joint_RM" type="fixed">
    <origin rpy="0.0 0.0 0.0" xyz="0.0 -0.073535 0.0"/>
    <parent link="body_link"/>
    <child link="leg_center_RM"/>
  </joint>
  <link name="leg_center_RM">
    <inertial>
      <origin rpy="0.0 0.0 0.0" xyz="0.0 0.0 0.0"/>
      <mass value="0.00001"/>
      <inertia ixx="1.0" ixy="0.0" ixz="0.0" iyy="1.0" iyz="0.0" izz="1.0"/>
    </inertial>
  </link>
  <!-- coxa -->
  <joint name="coxa_joint_RM" type="revolute">
    <origin rpy="0.0 0.0 -1.5707963267948966" xyz="0.0 0.0 0.0"/>
    <parent link="leg_center_RM"/>
    <child link="coxa_RM"/>
    <axis xyz="0.0 0.0 1.0"/>
    <limit effort="6.0" lower="-3.14" upper="3.14" velocity="0.524"/>
    <dynamics damping="0.7"/>
  </joint>
  <link name="coxa_RM">
    <visual>
      <origin rpy="0.0 0.0 0.0" xyz="0.0 0.0 0.0"/>
      <geometry>
        <mesh filename="package://jethexa_description/meshes/simplify/coxa.stl" scale="0.001 0.001 0.001"/>
      </geometry>
      <material name="">
        <color rgba="0.7 0.7 0.7 1"/>
      </material>
    </visual>
    <collision>
      <origin rpy="0.0 0.0 0.0" xyz="0.0 0.0 0.0"/>
      <geometry>
        <mesh filename="package://jethexa_description/meshes/simplify/coxa.stl" scale="0.001 0.001 0.001"/>
      </geometry>
      <material name="">
        <color rgba="0.7 0.7 0.7 1"/>
      </material>
    </collision>
    <inertial>
      <origin rpy="0.0 0.0 0.0" xyz="0.0 0.0 0.0"/>
      <mass value="0.00001"/>
      <inertia ixx="1.0" ixy="0.0" ixz="0.0" iyy="1.0" iyz="0.0" izz="1.0"/>
    </inertial>
  </link>
  <!-- femur -->
  <joint name="femur_joint_RM" type="revolute">
    <origin rpy="1.5707963267948966 0.0 0.0" xyz="0.04505032 0.0 0.0"/>
    <parent link="coxa_RM"/>
    <child link="femur_RM"/>
    <axis xyz="0.0 0.0 1"/>
    <limit effort="6.0" lower="-3.14" upper="3.14" velocity="0.524"/>
    <dynamics damping="0.7"/>
  </joint>
  <link name="femur_RM">
    <visual>
      <origin rpy="0.0 0.0 0.0" xyz="0.0 0.0 0.0"/>
      <geometry>
        <mesh filename="package://jethexa_description/meshes/simplify/R_femur.stl" scale="0.001 0.001 0.001"/>
      </geometry>
      <material name="">
        <color rgba="0.7 0.7 0.7 1"/>
      </material>
    </visual>
    <collision>
      <origin rpy="0.0 0.0 0" xyz="0.0 0.0 0.0"/>
      <geometry>
        <mesh filename="package://jethexa_description/meshes/simplify/R_femur.stl" scale="0.001 0.001 0.001"/>
      </geometry>
      <material name="">
        <color rgba="0.7 0.7 0.7 1"/>
      </material>
    </collision>
    <inertial>
      <origin rpy="0.0 0.0 1.0" xyz="0.0 0.0 0.0"/>
      <mass value="0.00001"/>
      <inertia ixx="1.0" ixy="0.0" ixz="0.0" iyy="1.0" iyz="0.0" izz="1.0"/>
    </inertial>
  </link>
  <!-- tibia -->
  <joint name="tibia_joint_RM" type="revolute">
    <origin rpy="0.0 0.0 -1.5707963267948966" xyz="0.07703 0.0 0.0"/>
    <parent link="femur_RM"/>
    <child link="tibia_RM"/>
    <axis xyz="0.0 0.0 1"/>
    <limit effort="6.0" lower="-3.14" upper="3.14" velocity="0.524"/>
    <dynamics damping="0.7"/>
  </joint>
  <link name="tibia_RM">
    <visual>
      <origin rpy="0.0 0.0 0.0" xyz="0.0 0.0 0.0"/>
      <geometry>
        <mesh filename="package://jethexa_description/meshes/simplify/R_tibia.stl" scale="0.001 0.001 0.001"/>
      </geometry>
      <material name="">
        <color rgba="0.7 0.7 0.7 1"/>
      </material>
    </visual>
    <collision>
      <origin rpy="0.0 0.0 0.0" xyz="0.0 0.0 0.0"/>
      <geometry>
        <mesh filename="package://jethexa_description/meshes/simplify/R_tibia.stl" scale="0.001 0.001 0.001"/>
      </geometry>
      <material name="">
        <color rgba="0.7 0.7 0.7 1"/>
      </material>
    </collision>
    <inertial>
      <origin rpy="0.0 0.0 0.0" xyz="0.0 0.0 0.0"/>
      <mass value="0.00001"/>
      <inertia ixx="1.0" ixy="0.0" ixz="0.0" iyy="1.0" iyz="0.0" izz="1.0"/>
    </inertial>
  </link>
  <!-- END -->
  <joint name="end_jointRM" type="fixed">
    <origin rpy="0.0 0.0 0.0" xyz="0.12 0.0 0.0"/>
    <parent link="tibia_RM"/>
    <child link="end_RM"/>
    <axis xyz="0.0 0.0 0.0"/>
  </joint>
  <link name="end_RM">
        </link>
  <!-- leg position -->
  <joint name="leg_center_joint_RF" type="fixed">
    <origin rpy="0.0 0.0 0.0" xyz="0.093205 -0.05098 0.0"/>
    <parent link="body_link"/>
    <child link="leg_center_RF"/>
  </joint>
  <link name="leg_center_RF">
    <inertial>
      <origin rpy="0.0 0.0 0.0" xyz="0.0 0.0 0.0"/>
      <mass value="0.00001"/>
      <inertia ixx="1.0" ixy="0.0" ixz="0.0" iyy="1.0" iyz="0.0" izz="1.0"/>
    </inertial>
  </link>
  <!-- coxa -->
  <joint name="coxa_joint_RF" type="revolute">
    <origin rpy="0.0 0.0 -0.7853981633974483" xyz="0.0 0.0 0.0"/>
    <parent link="leg_center_RF"/>
    <child link="coxa_RF"/>
    <axis xyz="0.0 0.0 1.0"/>
    <limit effort="6.0" lower="-3.14" upper="3.14" velocity="0.524"/>
    <dynamics damping="0.7"/>
  </joint>
  <link name="coxa_RF">
    <visual>
      <origin rpy="0.0 0.0 0.0" xyz="0.0 0.0 0.0"/>
      <geometry>
        <mesh filename="package://jethexa_description/meshes/simplify/coxa.stl" scale="0.001 0.001 0.001"/>
      </geometry>
      <material name="">
        <color rgba="0.7 0.7 0.7 1"/>
      </material>
    </visual>
    <collision>
      <origin rpy="0.0 0.0 0.0" xyz="0.0 0.0 0.0"/>
      <geometry>
        <mesh filename="package://jethexa_description/meshes/simplify/coxa.stl" scale="0.001 0.001 0.001"/>
      </geometry>
      <material name="">
        <color rgba="0.7 0.7 0.7 1"/>
      </material>
    </collision>
    <inertial>
      <origin rpy="0.0 0.0 0.0" xyz="0.0 0.0 0.0"/>
      <mass value="0.00001"/>
      <inertia ixx="1.0" ixy="0.0" ixz="0.0" iyy="1.0" iyz="0.0" izz="1.0"/>
    </inertial>
  </link>
  <!-- femur -->
  <joint name="femur_joint_RF" type="revolute">
    <origin rpy="1.5707963267948966 0.0 0.0" xyz="0.04505032 0.0 0.0"/>
    <parent link="coxa_RF"/>
    <child link="femur_RF"/>
    <axis xyz="0.0 0.0 1"/>
    <limit effort="6.0" lower="-3.14" upper="3.14" velocity="0.524"/>
    <dynamics damping="0.7"/>
  </joint>
  <link name="femur_RF">
    <visual>
      <origin rpy="0.0 0.0 0.0" xyz="0.0 0.0 0.0"/>
      <geometry>
        <mesh filename="package://jethexa_description/meshes/simplify/R_femur.stl" scale="0.001 0.001 0.001"/>
      </geometry>
      <material name="">
        <color rgba="0.7 0.7 0.7 1"/>
      </material>
    </visual>
    <collision>
      <origin rpy="0.0 0.0 0" xyz="0.0 0.0 0.0"/>
      <geometry>
        <mesh filename="package://jethexa_description/meshes/simplify/R_femur.stl" scale="0.001 0.001 0.001"/>
      </geometry>
      <material name="">
        <color rgba="0.7 0.7 0.7 1"/>
      </material>
    </collision>
    <inertial>
      <origin rpy="0.0 0.0 1.0" xyz="0.0 0.0 0.0"/>
      <mass value="0.00001"/>
      <inertia ixx="1.0" ixy="0.0" ixz="0.0" iyy="1.0" iyz="0.0" izz="1.0"/>
    </inertial>
  </link>
  <!-- tibia -->
  <joint name="tibia_joint_RF" type="revolute">
    <origin rpy="0.0 0.0 -1.5707963267948966" xyz="0.07703 0.0 0.0"/>
    <parent link="femur_RF"/>
    <child link="tibia_RF"/>
    <axis xyz="0.0 0.0 1"/>
    <limit effort="6.0" lower="-3.14" upper="3.14" velocity="0.524"/>
    <dynamics damping="0.7"/>
  </joint>
  <link name="tibia_RF">
    <visual>
      <origin rpy="0.0 0.0 0.0" xyz="0.0 0.0 0.0"/>
      <geometry>
        <mesh filename="package://jethexa_description/meshes/simplify/R_tibia.stl" scale="0.001 0.001 0.001"/>
      </geometry>
      <material name="">
        <color rgba="0.7 0.7 0.7 1"/>
      </material>
    </visual>
    <collision>
      <origin rpy="0.0 0.0 0.0" xyz="0.0 0.0 0.0"/>
      <geometry>
        <mesh filename="package://jethexa_description/meshes/simplify/R_tibia.stl" scale="0.001 0.001 0.001"/>
      </geometry>
      <material name="">
        <color rgba="0.7 0.7 0.7 1"/>
      </material>
    </collision>
    <inertial>
      <origin rpy="0.0 0.0 0.0" xyz="0.0 0.0 0.0"/>
      <mass value="0.00001"/>
      <inertia ixx="1.0" ixy="0.0" ixz="0.0" iyy="1.0" iyz="0.0" izz="1.0"/>
    </inertial>
  </link>
  <!-- END -->
  <joint name="end_jointRF" type="fixed">
    <origin rpy="0.0 0.0 0.0" xyz="0.12 0.0 0.0"/>
    <parent link="tibia_RF"/>
    <child link="end_RF"/>
    <axis xyz="0.0 0.0 0.0"/>
  </joint>
  <link name="end_RF">
        </link>
  <!-- leg position -->
  <joint name="leg_center_joint_LR" type="fixed">
    <origin rpy="0.0 0.0 0.0" xyz="-0.093205 0.05098 0.0"/>
    <parent link="body_link"/>
    <child link="leg_center_LR"/>
  </joint>
  <link name="leg_center_LR">
    <inertial>
      <origin rpy="0.0 0.0 0.0" xyz="0.0 0.0 0.0"/>
      <mass value="0.00001"/>
      <inertia ixx="1.0" ixy="0.0" ixz="0.0" iyy="1.0" iyz="0.0" izz="1.0"/>
    </inertial>
  </link>
  <!-- coxa -->
  <joint name="coxa_joint_LR" type="revolute">
    <origin rpy="0.0 0.0 2.356194490192345" xyz="0.0 0.0 0.0"/>
    <parent link="leg_center_LR"/>
    <child link="coxa_LR"/>
    <axis xyz="0.0 0.0 1.0"/>
    <limit effort="6.0" lower="-3.14" upper="3.14" velocity="0.524"/>
    <dynamics damping="0.7"/>
  </joint>
  <link name="coxa_LR">
    <visual>
      <origin rpy="0.0 0.0 0.0" xyz="0.0 0.0 0.0"/>
      <geometry>
        <mesh filename="package://jethexa_description/meshes/simplify/coxa.stl" scale="0.001 0.001 0.001"/>
      </geometry>
      <material name="">
        <color rgba="0.7 0.7 0.7 1"/>
      </material>
    </visual>
    <collision>
      <origin rpy="0.0 0.0 0.0" xyz="0.0 0.0 0.0"/>
      <geometry>
        <mesh filename="package://jethexa_description/meshes/simplify/coxa.stl" scale="0.001 0.001 0.001"/>
      </geometry>
      <material name="">
        <color rgba="0.7 0.7 0.7 1"/>
      </material>
    </collision>
    <inertial>
      <origin rpy="0.0 0.0 0.0" xyz="0.0 0.0 0.0"/>
      <mass value="0.00001"/>
      <inertia ixx="1.0" ixy="0.0" ixz="0.0" iyy="1.0" iyz="0.0" izz="1.0"/>
    </inertial>
  </link>
  <!-- femur -->
  <joint name="femur_joint_LR" type="revolute">
    <origin rpy="-1.5707963267948966 0.0 0.0" xyz="0.04505032 0.0 0.0"/>
    <parent link="coxa_LR"/>
    <child link="femur_LR"/>
    <axis xyz="0.0 0.0 -1"/>
    <limit effort="6.0" lower="-3.14" upper="3.14" velocity="0.524"/>
    <dynamics damping="0.7"/>
  </joint>
  <link name="femur_LR">
    <visual>
      <origin rpy="0.0 0.0 0.0" xyz="0.0 0.0 0.0"/>
      <geometry>
        <mesh filename="package://jethexa_description/meshes/simplify/L_femur.stl" scale="0.001 0.001 0.001"/>
      </geometry>
      <material name="">
        <color rgba="0.7 0.7 0.7 1"/>
      </material>
    </visual>
    <collision>
      <origin rpy="0.0 0.0 0" xyz="0.0 0.0 0.0"/>
      <geometry>
        <mesh filename="package://jethexa_description/meshes/simplify/L_femur.stl" scale="0.001 0.001 0.001"/>
      </geometry>
      <material name="">
        <color rgba="0.7 0.7 0.7 1"/>
      </material>
    </collision>
    <inertial>
      <origin rpy="0.0 0.0 1.0" xyz="0.0 0.0 0.0"/>
      <mass value="0.00001"/>
      <inertia ixx="1.0" ixy="0.0" ixz="0.0" iyy="1.0" iyz="0.0" izz="1.0"/>
    </inertial>
  </link>
  <!-- tibia -->
  <joint name="tibia_joint_LR" type="revolute">
    <origin rpy="0.0 0.0 1.5707963267948966" xyz="0.07703 0.0 0.0"/>
    <parent link="femur_LR"/>
    <child link="tibia_LR"/>
    <axis xyz="0.0 0.0 -1"/>
    <limit effort="6.0" lower="-3.14" upper="3.14" velocity="0.524"/>
    <dynamics damping="0.7"/>
  </joint>
  <link name="tibia_LR">
    <visual>
      <origin rpy="0.0 0.0 0.0" xyz="0.0 0.0 0.0"/>
      <geometry>
        <mesh filename="package://jethexa_description/meshes/simplify/L_tibia.stl" scale="0.001 0.001 0.001"/>
      </geometry>
      <material name="">
        <color rgba="0.7 0.7 0.7 1"/>
      </material>
    </visual>
    <collision>
      <origin rpy="0.0 0.0 0.0" xyz="0.0 0.0 0.0"/>
      <geometry>
        <mesh filename="package://jethexa_description/meshes/simplify/L_tibia.stl" scale="0.001 0.001 0.001"/>
      </geometry>
      <material name="">
        <color rgba="0.7 0.7 0.7 1"/>
      </material>
    </collision>
    <inertial>
      <origin rpy="0.0 0.0 0.0" xyz="0.0 0.0 0.0"/>
      <mass value="0.00001"/>
      <inertia ixx="1.0" ixy="0.0" ixz="0.0" iyy="1.0" iyz="0.0" izz="1.0"/>
    </inertial>
  </link>
  <!-- END -->
  <joint name="end_jointLR" type="fixed">
    <origin rpy="0.0 0.0 0.0" xyz="0.12 0.0 0.0"/>
    <parent link="tibia_LR"/>
    <child link="end_LR"/>
    <axis xyz="0.0 0.0 0.0"/>
  </joint>
  <link name="end_LR">
        </link>
  <!-- leg position -->
  <joint name="leg_center_joint_LM" type="fixed">
    <origin rpy="0.0 0.0 0.0" xyz="0.0 0.07353 0.0"/>
    <parent link="body_link"/>
    <child link="leg_center_LM"/>
  </joint>
  <link name="leg_center_LM">
    <inertial>
      <origin rpy="0.0 0.0 0.0" xyz="0.0 0.0 0.0"/>
      <mass value="0.00001"/>
      <inertia ixx="1.0" ixy="0.0" ixz="0.0" iyy="1.0" iyz="0.0" izz="1.0"/>
    </inertial>
  </link>
  <!-- coxa -->
  <joint name="coxa_joint_LM" type="revolute">
    <origin rpy="0.0 0.0 1.5707963267948966" xyz="0.0 0.0 0.0"/>
    <parent link="leg_center_LM"/>
    <child link="coxa_LM"/>
    <axis xyz="0.0 0.0 1.0"/>
    <limit effort="6.0" lower="-3.14" upper="3.14" velocity="0.524"/>
    <dynamics damping="0.7"/>
  </joint>
  <link name="coxa_LM">
    <visual>
      <origin rpy="0.0 0.0 0.0" xyz="0.0 0.0 0.0"/>
      <geometry>
        <mesh filename="package://jethexa_description/meshes/simplify/coxa.stl" scale="0.001 0.001 0.001"/>
      </geometry>
      <material name="">
        <color rgba="0.7 0.7 0.7 1"/>
      </material>
    </visual>
    <collision>
      <origin rpy="0.0 0.0 0.0" xyz="0.0 0.0 0.0"/>
      <geometry>
        <mesh filename="package://jethexa_description/meshes/simplify/coxa.stl" scale="0.001 0.001 0.001"/>
      </geometry>
      <material name="">
        <color rgba="0.7 0.7 0.7 1"/>
      </material>
    </collision>
    <inertial>
      <origin rpy="0.0 0.0 0.0" xyz="0.0 0.0 0.0"/>
      <mass value="0.00001"/>
      <inertia ixx="1.0" ixy="0.0" ixz="0.0" iyy="1.0" iyz="0.0" izz="1.0"/>
    </inertial>
  </link>
  <!-- femur -->
  <joint name="femur_joint_LM" type="revolute">
    <origin rpy="-1.5707963267948966 0.0 0.0" xyz="0.04505032 0.0 0.0"/>
    <parent link="coxa_LM"/>
    <child link="femur_LM"/>
    <axis xyz="0.0 0.0 -1"/>
    <limit effort="6.0" lower="-3.14" upper="3.14" velocity="0.524"/>
    <dynamics damping="0.7"/>
  </joint>
  <link name="femur_LM">
    <visual>
      <origin rpy="0.0 0.0 0.0" xyz="0.0 0.0 0.0"/>
      <geometry>
        <mesh filename="package://jethexa_description/meshes/simplify/L_femur.stl" scale="0.001 0.001 0.001"/>
      </geometry>
      <material name="">
        <color rgba="0.7 0.7 0.7 1"/>
      </material>
    </visual>
    <collision>
      <origin rpy="0.0 0.0 0" xyz="0.0 0.0 0.0"/>
      <geometry>
        <mesh filename="package://jethexa_description/meshes/simplify/L_femur.stl" scale="0.001 0.001 0.001"/>
      </geometry>
      <material name="">
        <color rgba="0.7 0.7 0.7 1"/>
      </material>
    </collision>
    <inertial>
      <origin rpy="0.0 0.0 1.0" xyz="0.0 0.0 0.0"/>
      <mass value="0.00001"/>
      <inertia ixx="1.0" ixy="0.0" ixz="0.0" iyy="1.0" iyz="0.0" izz="1.0"/>
    </inertial>
  </link>
  <!-- tibia -->
  <joint name="tibia_joint_LM" type="revolute">
    <origin rpy="0.0 0.0 1.5707963267948966" xyz="0.07703 0.0 0.0"/>
    <parent link="femur_LM"/>
    <child link="tibia_LM"/>
    <axis xyz="0.0 0.0 -1"/>
    <limit effort="6.0" lower="-3.14" upper="3.14" velocity="0.524"/>
    <dynamics damping="0.7"/>
  </joint>
  <link name="tibia_LM">
    <visual>
      <origin rpy="0.0 0.0 0.0" xyz="0.0 0.0 0.0"/>
      <geometry>
        <mesh filename="package://jethexa_description/meshes/simplify/L_tibia.stl" scale="0.001 0.001 0.001"/>
      </geometry>
      <material name="">
        <color rgba="0.7 0.7 0.7 1"/>
      </material>
    </visual>
    <collision>
      <origin rpy="0.0 0.0 0.0" xyz="0.0 0.0 0.0"/>
      <geometry>
        <mesh filename="package://jethexa_description/meshes/simplify/L_tibia.stl" scale="0.001 0.001 0.001"/>
      </geometry>
      <material name="">
        <color rgba="0.7 0.7 0.7 1"/>
      </material>
    </collision>
    <inertial>
      <origin rpy="0.0 0.0 0.0" xyz="0.0 0.0 0.0"/>
      <mass value="0.00001"/>
      <inertia ixx="1.0" ixy="0.0" ixz="0.0" iyy="1.0" iyz="0.0" izz="1.0"/>
    </inertial>
  </link>
  <!-- END -->
  <joint name="end_jointLM" type="fixed">
    <origin rpy="0.0 0.0 0.0" xyz="0.12 0.0 0.0"/>
    <parent link="tibia_LM"/>
    <child link="end_LM"/>
    <axis xyz="0.0 0.0 0.0"/>
  </joint>
  <link name="end_LM">
        </link>
  <!-- leg position -->
  <joint name="leg_center_joint_LF" type="fixed">
    <origin rpy="0.0 0.0 0.0" xyz="0.093205 0.05098 0.0"/>
    <parent link="body_link"/>
    <child link="leg_center_LF"/>
  </joint>
  <link name="leg_center_LF">
    <inertial>
      <origin rpy="0.0 0.0 0.0" xyz="0.0 0.0 0.0"/>
      <mass value="0.00001"/>
      <inertia ixx="1.0" ixy="0.0" ixz="0.0" iyy="1.0" iyz="0.0" izz="1.0"/>
    </inertial>
  </link>
  <!-- coxa -->
  <joint name="coxa_joint_LF" type="revolute">
    <origin rpy="0.0 0.0 0.7853981633974483" xyz="0.0 0.0 0.0"/>
    <parent link="leg_center_LF"/>
    <child link="coxa_LF"/>
    <axis xyz="0.0 0.0 1.0"/>
    <limit effort="6.0" lower="-3.14" upper="3.14" velocity="0.524"/>
    <dynamics damping="0.7"/>
  </joint>
  <link name="coxa_LF">
    <visual>
      <origin rpy="0.0 0.0 0.0" xyz="0.0 0.0 0.0"/>
      <geometry>
        <mesh filename="package://jethexa_description/meshes/simplify/coxa.stl" scale="0.001 0.001 0.001"/>
      </geometry>
      <material name="">
        <color rgba="0.7 0.7 0.7 1"/>
      </material>
    </visual>
    <collision>
      <origin rpy="0.0 0.0 0.0" xyz="0.0 0.0 0.0"/>
      <geometry>
        <mesh filename="package://jethexa_description/meshes/simplify/coxa.stl" scale="0.001 0.001 0.001"/>
      </geometry>
      <material name="">
        <color rgba="0.7 0.7 0.7 1"/>
      </material>
    </collision>
    <inertial>
      <origin rpy="0.0 0.0 0.0" xyz="0.0 0.0 0.0"/>
      <mass value="0.00001"/>
      <inertia ixx="1.0" ixy="0.0" ixz="0.0" iyy="1.0" iyz="0.0" izz="1.0"/>
    </inertial>
  </link>
  <!-- femur -->
  <joint name="femur_joint_LF" type="revolute">
    <origin rpy="-1.5707963267948966 0.0 0.0" xyz="0.04505032 0.0 0.0"/>
    <parent link="coxa_LF"/>
    <child link="femur_LF"/>
    <axis xyz="0.0 0.0 -1"/>
    <limit effort="6.0" lower="-3.14" upper="3.14" velocity="0.524"/>
    <dynamics damping="0.7"/>
  </joint>
  <link name="femur_LF">
    <visual>
      <origin rpy="0.0 0.0 0.0" xyz="0.0 0.0 0.0"/>
      <geometry>
        <mesh filename="package://jethexa_description/meshes/simplify/L_femur.stl" scale="0.001 0.001 0.001"/>
      </geometry>
      <material name="">
        <color rgba="0.7 0.7 0.7 1"/>
      </material>
    </visual>
    <collision>
      <origin rpy="0.0 0.0 0" xyz="0.0 0.0 0.0"/>
      <geometry>
        <mesh filename="package://jethexa_description/meshes/simplify/L_femur.stl" scale="0.001 0.001 0.001"/>
      </geometry>
      <material name="">
        <color rgba="0.7 0.7 0.7 1"/>
      </material>
    </collision>
    <inertial>
      <origin rpy="0.0 0.0 1.0" xyz="0.0 0.0 0.0"/>
      <mass value="0.00001"/>
      <inertia ixx="1.0" ixy="0.0" ixz="0.0" iyy="1.0" iyz="0.0" izz="1.0"/>
    </inertial>
  </link>
  <!-- tibia -->
  <joint name="tibia_joint_LF" type="revolute">
    <origin rpy="0.0 0.0 1.5707963267948966" xyz="0.07703 0.0 0.0"/>
    <parent link="femur_LF"/>
    <child link="tibia_LF"/>
    <axis xyz="0.0 0.0 -1"/>
    <limit effort="6.0" lower="-3.14" upper="3.14" velocity="0.524"/>
    <dynamics damping="0.7"/>
  </joint>
  <link name="tibia_LF">
    <visual>
      <origin rpy="0.0 0.0 0.0" xyz="0.0 0.0 0.0"/>
      <geometry>
        <mesh filename="package://jethexa_description/meshes/simplify/L_tibia.stl" scale="0.001 0.001 0.001"/>
      </geometry>
      <material name="">
        <color rgba="0.7 0.7 0.7 1"/>
      </material>
    </visual>
    <collision>
      <origin rpy="0.0 0.0 0.0" xyz="0.0 0.0 0.0"/>
      <geometry>
        <mesh filename="package://jethexa_description/meshes/simplify/L_tibia.stl" scale="0.001 0.001 0.001"/>
      </geometry>
      <material name="">
        <color rgba="0.7 0.7 0.7 1"/>
      </material>
    </collision>
    <inertial>
      <origin rpy="0.0 0.0 0.0" xyz="0.0 0.0 0.0"/>
      <mass value="0.00001"/>
      <inertia ixx="1.0" ixy="0.0" ixz="0.0" iyy="1.0" iyz="0.0" izz="1.0"/>
    </inertial>
  </link>
  <!-- END -->
  <joint name="end_jointLF" type="fixed">
    <origin rpy="0.0 0.0 0.0" xyz="0.12 0.0 0.0"/>
    <parent link="tibia_LF"/>
    <child link="end_LF"/>
    <axis xyz="0.0 0.0 0.0"/>
  </joint>
  <link name="end_LF">
        </link>
</robot>
